[2022-10-01 01:53:26,396] {taskinstance.py:903} INFO - Dependencies all met for <TaskInstance: daily_data_processing_pipeline.dataset2.extract 2022-10-01T01:53:24.465878+00:00 [queued]>
[2022-10-01 01:53:26,412] {taskinstance.py:903} INFO - Dependencies all met for <TaskInstance: daily_data_processing_pipeline.dataset2.extract 2022-10-01T01:53:24.465878+00:00 [queued]>
[2022-10-01 01:53:26,413] {taskinstance.py:1094} INFO - 
--------------------------------------------------------------------------------
[2022-10-01 01:53:26,414] {taskinstance.py:1095} INFO - Starting attempt 1 of 1
[2022-10-01 01:53:26,414] {taskinstance.py:1096} INFO - 
--------------------------------------------------------------------------------
[2022-10-01 01:53:26,423] {taskinstance.py:1114} INFO - Executing <Task(_PythonDecoratedOperator): dataset2.extract> on 2022-10-01T01:53:24.465878+00:00
[2022-10-01 01:53:26,470] {standard_task_runner.py:52} INFO - Started process 3891 to run task
[2022-10-01 01:53:26,473] {standard_task_runner.py:76} INFO - Running: ['***', 'tasks', 'run', 'daily_data_processing_pipeline', 'dataset2.extract', '2022-10-01T01:53:24.465878+00:00', '--job-id', '15', '--pool', 'default_pool', '--raw', '--subdir', 'DAGS_FOLDER/dag_schedule.py', '--cfg-path', '/tmp/tmpfuv2c72z', '--error-file', '/tmp/tmp8joulk5w']
[2022-10-01 01:53:26,474] {standard_task_runner.py:77} INFO - Job 15: Subtask dataset2.extract
[2022-10-01 01:53:26,519] {logging_mixin.py:109} INFO - Running <TaskInstance: daily_data_processing_pipeline.dataset2.extract 2022-10-01T01:53:24.465878+00:00 [running]> on host f7d8021d0ce4
[2022-10-01 01:53:26,564] {taskinstance.py:1253} INFO - Exporting the following env vars:
AIRFLOW_CTX_DAG_OWNER=***
AIRFLOW_CTX_DAG_ID=daily_data_processing_pipeline
AIRFLOW_CTX_TASK_ID=dataset2.extract
AIRFLOW_CTX_EXECUTION_DATE=2022-10-01T01:53:24.465878+00:00
AIRFLOW_CTX_DAG_RUN_ID=manual__2022-10-01T01:53:24.465878+00:00
[2022-10-01 01:53:26,565] {dag_schedule.py:41} INFO - Input File Path
[2022-10-01 01:53:26,566] {dag_schedule.py:42} INFO - input/dataset2.csv
[2022-10-01 01:53:26,567] {taskinstance.py:1462} ERROR - Task failed with exception
Traceback (most recent call last):
  File "/home/airflow/.local/lib/python3.6/site-packages/airflow/models/taskinstance.py", line 1164, in _run_raw_task
    self._prepare_and_execute_task_with_callbacks(context, task)
  File "/home/airflow/.local/lib/python3.6/site-packages/airflow/models/taskinstance.py", line 1282, in _prepare_and_execute_task_with_callbacks
    result = self._execute_task(context, task_copy)
  File "/home/airflow/.local/lib/python3.6/site-packages/airflow/models/taskinstance.py", line 1312, in _execute_task
    result = task_copy.execute(context=context)
  File "/home/airflow/.local/lib/python3.6/site-packages/airflow/decorators/base.py", line 134, in execute
    return_value = super().execute(context)
  File "/home/airflow/.local/lib/python3.6/site-packages/airflow/operators/python.py", line 150, in execute
    return_value = self.execute_callable()
  File "/home/airflow/.local/lib/python3.6/site-packages/airflow/operators/python.py", line 161, in execute_callable
    return self.python_callable(*self.op_args, **self.op_kwargs)
  File "/opt/airflow/dags/dag_schedule.py", line 44, in extract
    df = pd.read_csv(filepath)
  File "/home/airflow/.local/lib/python3.6/site-packages/pandas/io/parsers.py", line 688, in read_csv
    return _read(filepath_or_buffer, kwds)
  File "/home/airflow/.local/lib/python3.6/site-packages/pandas/io/parsers.py", line 454, in _read
    parser = TextFileReader(fp_or_buf, **kwds)
  File "/home/airflow/.local/lib/python3.6/site-packages/pandas/io/parsers.py", line 948, in __init__
    self._make_engine(self.engine)
  File "/home/airflow/.local/lib/python3.6/site-packages/pandas/io/parsers.py", line 1180, in _make_engine
    self._engine = CParserWrapper(self.f, **self.options)
  File "/home/airflow/.local/lib/python3.6/site-packages/pandas/io/parsers.py", line 2010, in __init__
    self._reader = parsers.TextReader(src, **kwds)
  File "pandas/_libs/parsers.pyx", line 382, in pandas._libs.parsers.TextReader.__cinit__
  File "pandas/_libs/parsers.pyx", line 674, in pandas._libs.parsers.TextReader._setup_parser_source
FileNotFoundError: [Errno 2] No such file or directory: 'input/dataset2.csv'
[2022-10-01 01:53:26,576] {taskinstance.py:1512} INFO - Marking task as FAILED. dag_id=daily_data_processing_pipeline, task_id=dataset2.extract, execution_date=20221001T015324, start_date=20221001T015326, end_date=20221001T015326
[2022-10-01 01:53:26,605] {local_task_job.py:151} INFO - Task exited with return code 1
[2022-10-01 01:53:26,631] {local_task_job.py:261} INFO - 0 downstream tasks scheduled from follow-on schedule check
