[2022-10-01 01:59:01,856] {taskinstance.py:903} INFO - Dependencies all met for <TaskInstance: daily_data_processing_pipeline.dataset2.transform 2022-10-01T01:58:57.767978+00:00 [queued]>
[2022-10-01 01:59:01,872] {taskinstance.py:903} INFO - Dependencies all met for <TaskInstance: daily_data_processing_pipeline.dataset2.transform 2022-10-01T01:58:57.767978+00:00 [queued]>
[2022-10-01 01:59:01,872] {taskinstance.py:1094} INFO - 
--------------------------------------------------------------------------------
[2022-10-01 01:59:01,873] {taskinstance.py:1095} INFO - Starting attempt 1 of 1
[2022-10-01 01:59:01,874] {taskinstance.py:1096} INFO - 
--------------------------------------------------------------------------------
[2022-10-01 01:59:01,881] {taskinstance.py:1114} INFO - Executing <Task(_PythonDecoratedOperator): dataset2.transform> on 2022-10-01T01:58:57.767978+00:00
[2022-10-01 01:59:01,886] {standard_task_runner.py:52} INFO - Started process 4495 to run task
[2022-10-01 01:59:01,890] {standard_task_runner.py:76} INFO - Running: ['***', 'tasks', 'run', 'daily_data_processing_pipeline', 'dataset2.transform', '2022-10-01T01:58:57.767978+00:00', '--job-id', '24', '--pool', 'default_pool', '--raw', '--subdir', 'DAGS_FOLDER/dag_schedule.py', '--cfg-path', '/tmp/tmphqqgs4rw', '--error-file', '/tmp/tmpdx7df5ja']
[2022-10-01 01:59:01,891] {standard_task_runner.py:77} INFO - Job 24: Subtask dataset2.transform
[2022-10-01 01:59:01,927] {logging_mixin.py:109} INFO - Running <TaskInstance: daily_data_processing_pipeline.dataset2.transform 2022-10-01T01:58:57.767978+00:00 [running]> on host f7d8021d0ce4
[2022-10-01 01:59:02,082] {taskinstance.py:1253} INFO - Exporting the following env vars:
AIRFLOW_CTX_DAG_OWNER=***
AIRFLOW_CTX_DAG_ID=daily_data_processing_pipeline
AIRFLOW_CTX_TASK_ID=dataset2.transform
AIRFLOW_CTX_EXECUTION_DATE=2022-10-01T01:58:57.767978+00:00
AIRFLOW_CTX_DAG_RUN_ID=manual__2022-10-01T01:58:57.767978+00:00
[2022-10-01 01:59:02,084] {taskinstance.py:1462} ERROR - Task failed with exception
Traceback (most recent call last):
  File "/home/airflow/.local/lib/python3.6/site-packages/airflow/models/taskinstance.py", line 1164, in _run_raw_task
    self._prepare_and_execute_task_with_callbacks(context, task)
  File "/home/airflow/.local/lib/python3.6/site-packages/airflow/models/taskinstance.py", line 1282, in _prepare_and_execute_task_with_callbacks
    result = self._execute_task(context, task_copy)
  File "/home/airflow/.local/lib/python3.6/site-packages/airflow/models/taskinstance.py", line 1312, in _execute_task
    result = task_copy.execute(context=context)
  File "/home/airflow/.local/lib/python3.6/site-packages/airflow/decorators/base.py", line 134, in execute
    return_value = super().execute(context)
  File "/home/airflow/.local/lib/python3.6/site-packages/airflow/operators/python.py", line 150, in execute
    return_value = self.execute_callable()
  File "/home/airflow/.local/lib/python3.6/site-packages/airflow/operators/python.py", line 161, in execute_callable
    return self.python_callable(*self.op_args, **self.op_kwargs)
  File "/opt/airflow/dags/dag_schedule.py", line 53, in transform
    df['name'].replace('', np.nan, inplace=True)
TypeError: list indices must be integers or slices, not str
[2022-10-01 01:59:02,092] {taskinstance.py:1512} INFO - Marking task as FAILED. dag_id=daily_data_processing_pipeline, task_id=dataset2.transform, execution_date=20221001T015857, start_date=20221001T015901, end_date=20221001T015902
[2022-10-01 01:59:02,142] {local_task_job.py:151} INFO - Task exited with return code 1
[2022-10-01 01:59:02,166] {local_task_job.py:261} INFO - 0 downstream tasks scheduled from follow-on schedule check
